const { readFile } = require("fs");

const getText = (path) => {
  return new Promise((resolve, reject) => {
    readFile(path, "utf8", (err, data) => {
      if (err) {
        reject(err);
      } else {
        resolve(data);
      }
    });
  });
};

getText("./content/first.txt")
  .then((result) => console.log(result))
  .catch((err) => console.log(err));

// '.then' method is executed immediately after the promise is resolved where 'result' is the resolved value.
// '.catch' method is used if promise is rejected where 'err' is the reject reason?
